<?xml version="1.0" ?>
<sdf version='1.5'>
  <model name='uav'>

    <link name='base_link'>
      <pose frame=''>0 0 0 0 -0 0</pose>
      <inertial>
        <pose>-0.0225178215569021 -6.57896227218568E-06 0.0139624643866879 0 -0 0</pose>
        <mass>0.961089</mass>
        <inertia>
          <ixx>0.00127644805029181</ixx>
          <ixy>3.54202350999824E-08</ixy>
          <ixz>-7.517755485557E-08</ixz>
          <iyy>0.00522903</iyy>
          <iyz>0.00189227634416466</iyz>
          <izz>0.00309210466393083</izz>
        </inertia>
      </inertial>
      <collision name='base_link_collision'>
        <pose>0 0 0 0 -0 0</pose>
        <geometry>
          <mesh>
            <scale>1 1 1</scale>
            <uri>model://uav/meshes/base_link.STL</uri>
          </mesh>
        </geometry>
      </collision>
      <visual name='base_link_visual'>
        <pose>0 0 0 0 -0 0</pose>
        <geometry>
          <mesh>
            <scale>1 1 1</scale>
            <uri>model://uav/meshes/base_link.STL</uri>
          </mesh>
        </geometry>
      </visual>
      <gravity>1</gravity>
      <velocity_decay/>
    </link>
    
    <joint name="camera" type="fixed">
      <pose relative_to='base_link'>0.15532 0.0017162 -0.0013741 0 1.5708 0</pose>
      <parent>base_link</parent>
      <child>camera_link</child>
    </joint>

    <link name="camera_link">
      <pose relative_to='camera'>0 0 0 0 0 0</pose>
      <inertial>
        <pose>0.000136232063015659 -0.0017048035419846 -0.011444044647428 0 0 0</pose>
        <mass>0.107909832749777</mass>
        <inertia>
          <ixx>7.02561489057724E-05</ixx>
          <ixy>2.88922877896695E-10</ixy>
          <ixz>-4.93709713285397E-08</ixz>
          <iyy>7.70986396723321E-06</iyy>
          <iyz>-1.79670593839534E-08</iyz>
          <izz>7.125435257498E-05</izz>
        </inertia>
      </inertial>
      <collision name='camera_link_collision'>
       <pose>0 0 0 0 0 0</pose>
        <geometry>
          <mesh>
            <scale>1 1 1</scale>
            <uri>model://uav/meshes/camera_link.STL</uri>
          </mesh>
        </geometry>
      </collision>
      <visual name='camera_link_visual'>
        <pose>0 0 0 0 0 0</pose>
        <geometry>
          <mesh>
            <scale>1 1 1</scale>
            <uri>model://uav/meshes/camera_link.STL</uri>
          </mesh>
        </geometry>
      </visual>
      <gravity>1</gravity>
      <velocity_decay/>
    </link>


    <joint name="lidar" type="fixed">
      <pose relative_to='base_link'>0.080904 0 0.074681 0 0.2618 0</pose>
      <parent>base_link</parent>
      <child>lidar_link</child>
    </joint>

    <link name="lidar_link">
      <pose relative_to='lidar'>0 0 0 0 0 0</pose>
      <inertial>
        <pose>-0.000225895985044744 -2.48539042069229E-07 -0.0356306802252529 0 0 0</pose>
        <mass>0.126556231362929</mass>
        <inertia>
          <ixx>3.65033273726769E-05</ixx>
          <ixy>-9.06996386175696E-11</ixy>
          <ixz>3.04767232794276E-07</ixz>
          <iyy>3.97162828413759E-05</iyy>
          <iyz>1.45228125953335E-10</iyz>
          <izz>5.81891052137894E-05</izz>
        </inertia>
      </inertial>
       <collision name='lidar_link_collision'>
       <pose>0 0 0 0 0 0</pose>
        <geometry>
          <mesh>
            <scale>1 1 1</scale>
            <uri>model://uav/meshes/lidar_link.STL</uri>
          </mesh>
        </geometry>
      </collision>
      <visual name='lidar_link_visual'>
        <pose>0 0 0 0 0 0</pose>
        <geometry>
          <mesh>
            <scale>1 1 1</scale>
            <uri>model://uav/meshes/lidar_link.STL</uri>
          </mesh>
        </geometry>
      </visual>
      <sensor name='laser_livox' type='ray'>
        <visualize>1</visualize>
        <update_rate>10</update_rate>
        <always_on>1</always_on>
        <plugin name='gazebo_ros_laser_controller' filename='liblivox_laser_simulation.so'>
          <ray>
			  <scan>
				  <horizontal>
				    <samples>100</samples>
				    <resolution>1</resolution>
				    <min_angle>0</min_angle>
            			    <max_angle>6.28</max_angle>
				  </horizontal>
				  <vertical>
				    <samples>360</samples>
				    <resolution>1</resolution>
				    <min_angle>-0.0561995544444</min_angle>
           			    <max_angle>0.981223276667</max_angle>
				  </vertical>
			  </scan>
			  <range>
				  <min>0.1</min>
				  <max>30</max>
				  <resolution>0.02</resolution>
			  </range>
			  <noise>
				  <type>gaussian</type>
				  <mean>0.0</mean>
				  <stddev>0.0</stddev>
			  </noise>
			  </ray>
          <frameName>laser_livox_link</frameName>
          <visualize>1</visualize>
          <samples>24000</samples>
          <downsample>1</downsample>
          <csv_file_name>/home/tuxuan/A-Program/tx_ws/src/livox_laser_simulation/scan_mode/mid360.csv</csv_file_name>
          <ros_topic>/scan</ros_topic>
        </plugin>
        <pose>0 0 0 0 0 0</pose>
      </sensor>
      <gravity>1</gravity>
      <velocity_decay/>
    </link>

       <joint name='propeller_1' type='revolute'>
      <pose relative_to='base_link'>0.081317 0.081317 -0.0264 0 -0 0</pose>
      <parent>base_link</parent>
      <child>propeller_1_link</child>
      <axis>
        <xyz>0 0 -1</xyz>
        <limit>
          <lower>-1e+16</lower>
          <upper>1e+16</upper>
        </limit>
        <dynamics>
          <spring_reference>0</spring_reference>
          <spring_stiffness>0</spring_stiffness>
        </dynamics>
      </axis>
    </joint>

    <link name='propeller_1_link'>
      <pose relative_to='propeller_1'>0 0 0 0 -0 0</pose>
      <inertial>
        <pose>-0 -0 0.003491 0 -0 0</pose>
        <mass>0.0012983</mass>
        <inertia>
          <ixx>5.4247e-07</ixx>
          <ixy>-3.2114e-14</ixy>
          <ixz>8.3771e-14</ixz>
          <iyy>5.4246e-07</iyy>
          <iyz>5.8084e-15</iyz>
          <izz>1.0787e-06</izz>
        </inertia>
      </inertial>

      <collision name='propeller_1_link_collision'>
        <pose>0 0 0 0 -0 0</pose>
        <geometry>
          <mesh>
            <scale>1 1 1</scale>
            <uri>model://uav/meshes/propeller_1_link.STL</uri>
          </mesh>
        </geometry>
      </collision>
      <visual name='propeller_1_link_visual'>
        <pose>0 0 0 0 -0 0</pose>
        <geometry>
          <mesh>
            <scale>1 1 1</scale>
            <uri>model://uav/meshes/propeller_1_link.STL</uri>
          </mesh>
        </geometry>
      </visual>
      <gravity>1</gravity>
      <velocity_decay/>
    </link>

    <joint name='propeller_2' type='revolute'>
      <pose relative_to='base_link'>0.081317 -0.081317 -0.0264 0 -0 0</pose>
      <parent>base_link</parent>
      <child>propeller_2_link</child>
      <axis>
        <xyz>0 0 1</xyz>
        <limit>
          <lower>-1e+16</lower>
          <upper>1e+16</upper>
        </limit>
        <dynamics>
          <spring_reference>0</spring_reference>
          <spring_stiffness>0</spring_stiffness>
        </dynamics>
      </axis>
    </joint>

    <link name='propeller_2_link'>
      <pose relative_to='propeller_2'>0 0 0 0 -0 0</pose>
      <inertial>
        <pose>-0 -0 0.003491 0 -0 0</pose>
        <mass>0.00129831</mass>
        <inertia>
          <ixx>5.42465e-07</ixx>
          <ixy>-1.52128e-13</ixy>
          <ixz>6.07542e-14</ixz>
          <iyy>5.42465e-07</iyy>
          <iyz>2.54999e-14</iyz>
          <izz>1.07868e-06</izz>
        </inertia>
      </inertial>
      <collision name='propeller_2_link_collision'>
        <pose>0 0 0 0 -0 0</pose>
        <geometry>
          <mesh>
            <scale>1 1 1</scale>
            <uri>model://uav/meshes/propeller_2_link.STL</uri>
          </mesh>
        </geometry>
      </collision>
      <visual name='propeller_2_link_visual'>
        <pose>0 0 0 0 -0 0</pose>
        <geometry>
          <mesh>
            <scale>1 1 1</scale>
            <uri>model://uav/meshes/propeller_2_link.STL</uri>
          </mesh>
        </geometry>
      </visual>
      <gravity>1</gravity>
      <velocity_decay/>
    </link>
    
    <joint name='propeller_3' type='revolute'>
      <pose relative_to='base_link'>-0.081317 -0.081317 -0.0264 0 -0 0</pose>
      <parent>base_link</parent>
      <child>propeller_3_link</child>
      <axis>
        <xyz>0 0 -1</xyz>
        <limit>
          <lower>-1e+16</lower>
          <upper>1e+16</upper>
        </limit>
        <dynamics>
          <spring_reference>0</spring_reference>
          <spring_stiffness>0</spring_stiffness>
        </dynamics>
      </axis>
    </joint>

    <link name='propeller_3_link'>
      <pose relative_to='propeller_3'>0 0 0 0 -0 0</pose>
      <inertial>
        <pose>0 -0 0.003491 0 -0 0</pose>
        <mass>0.0012983</mass>
        <inertia>
          <ixx>5.4246e-07</ixx>
          <ixy>1.5689e-13</ixy>
          <ixz>4.6336e-14</ixz>
          <iyy>5.4246e-07</iyy>
          <iyz>-1.3257e-14</iyz>
          <izz>1.0787e-06</izz>
        </inertia>
      </inertial>
      <collision name='propeller_3_link_collision'>
        <pose>0 0 0 0 -0 0</pose>
        <geometry>
          <mesh>
            <scale>1 1 1</scale>
            <uri>model://uav/meshes/propeller_3_link.STL</uri>
          </mesh>
        </geometry>
      </collision>
      <visual name='propeller_3_link_visual'>
        <pose>0 0 0 0 -0 0</pose>
        <geometry>
          <mesh>
            <scale>1 1 1</scale>
            <uri>model://uav/meshes/propeller_3_link.STL</uri>
          </mesh>
        </geometry>
      </visual>
      <gravity>1</gravity>
      <velocity_decay/>
    </link>

    <joint name='propeller_4' type='revolute'>
      <pose relative_to='base_link'>-0.081317 0.081317 -0.0264 0 -0 0</pose>
      <parent>base_link</parent>
      <child>propeller_4_link</child>
      <axis>
        <xyz>0 0 1</xyz>
        <limit>
          <lower>-1e+16</lower>
          <upper>1e+16</upper>
        </limit>
        <dynamics>
          <spring_reference>0</spring_reference>
          <spring_stiffness>0</spring_stiffness>
        </dynamics>
      </axis>
    </joint>

    <link name='propeller_4_link'>
      <pose relative_to='propeller_4'>0 0 0 0 -0 0</pose>
      <inertial>
        <pose>0 -0 0.003491 0 -0 0</pose>
        <mass>0.0012983</mass>
        <inertia>
          <ixx>5.4246e-07</ixx>
          <ixy>5.4591e-16</ixy>
          <ixz>-6.3118e-16</ixz>
          <iyy>5.4246e-07</iyy>
          <iyz>8.0385e-14</iyz>
          <izz>1.0787e-06</izz>
        </inertia>
      </inertial>
      <collision name='propeller_4_link_collision'>
        <pose>0 0 0 0 -0 0</pose>
        <geometry>
          <mesh>
            <scale>1 1 1</scale>
            <uri>model://uav/meshes/propeller_4_link.STL</uri>
          </mesh>
        </geometry>
      </collision>
      <visual name='propeller_4_link_visual'>
        <pose>0 0 0 0 -0 0</pose>
        <geometry>
          <mesh>
            <scale>1 1 1</scale>
            <uri>model://uav/meshes/propeller_4_link.STL</uri>
          </mesh>
        </geometry>
      </visual>
      <gravity>1</gravity>
      <velocity_decay/>
    </link>

    <link name='/imu_link'>
      <pose>0 0 0.02 0 0 0</pose>
      <inertial>
        <pose>0 0 0 0 0 0</pose>
        <mass>0.015</mass>
        <inertia>
          <ixx>1e-05</ixx>
          <ixy>0</ixy>
          <ixz>0</ixz>
          <iyy>1e-05</iyy>
          <iyz>0</iyz>
          <izz>1e-05</izz>
        </inertia>
      </inertial>
    </link>
    <joint name='/imu_joint' type='fixed'>
      <child>/imu_link</child>
      <parent>base_link</parent>
      <axis>
        <xyz>1 0 0</xyz>
        <limit>
          <lower>0</lower>
          <upper>0</upper>
          <effort>0</effort>
          <velocity>0</velocity>
        </limit>
        <dynamics>
          <spring_reference>0</spring_reference>
          <spring_stiffness>0</spring_stiffness>
        </dynamics>
        <use_parent_model_frame>1</use_parent_model_frame>
      </axis>
    </joint>
    
    <plugin name='rosbag' filename='libgazebo_multirotor_base_plugin.so'>
      <robotNamespace/>
      <linkName>base_link</linkName>
      <rotorVelocitySlowdownSim>10</rotorVelocitySlowdownSim>
    </plugin>
    <plugin name='front_right_motor_model' filename='libgazebo_motor_model.so'>
      <robotNamespace/>
      <jointName>propeller_2</jointName>
      <linkName>propeller_2_link</linkName>
      <turningDirection>ccw</turningDirection>
      <timeConstantUp>0.0125</timeConstantUp>
      <timeConstantDown>0.025</timeConstantDown>
      <maxRotVelocity>1100</maxRotVelocity>
      <motorConstant>5.84e-06</motorConstant>
      <momentConstant>0.06</momentConstant>
      <commandSubTopic>/gazebo/command/motor_speed</commandSubTopic>
      <motorNumber>0</motorNumber>
      <rotorDragCoefficient>0.000175</rotorDragCoefficient>
      <rollingMomentCoefficient>1e-06</rollingMomentCoefficient>
      <motorSpeedPubTopic>/motor_speed/0</motorSpeedPubTopic>
      <rotorVelocitySlowdownSim>10</rotorVelocitySlowdownSim>
    </plugin>
    <plugin name='back_left_motor_model' filename='libgazebo_motor_model.so'>
      <robotNamespace/>
      <jointName>propeller_4</jointName>
      <linkName>propeller_4_link</linkName>
      <turningDirection>ccw</turningDirection>
      <timeConstantUp>0.0125</timeConstantUp>
      <timeConstantDown>0.025</timeConstantDown>
      <maxRotVelocity>1100</maxRotVelocity>
      <motorConstant>5.84e-06</motorConstant>
      <momentConstant>0.06</momentConstant>
      <commandSubTopic>/gazebo/command/motor_speed</commandSubTopic>
      <motorNumber>1</motorNumber>
      <rotorDragCoefficient>0.000175</rotorDragCoefficient>
      <rollingMomentCoefficient>1e-06</rollingMomentCoefficient>
      <motorSpeedPubTopic>/motor_speed/1</motorSpeedPubTopic>
      <rotorVelocitySlowdownSim>10</rotorVelocitySlowdownSim>
    </plugin>
      <plugin name='front_left_motor_model' filename='libgazebo_motor_model.so'>
      <robotNamespace/>
      <jointName>propeller_1</jointName>
      <linkName>propeller_1_link</linkName>
      <turningDirection>cw</turningDirection>
      <timeConstantUp>0.0125</timeConstantUp>
      <timeConstantDown>0.025</timeConstantDown>
      <maxRotVelocity>1100</maxRotVelocity>
      <motorConstant>5.84e-06</motorConstant>
      <momentConstant>0.06</momentConstant>
      <commandSubTopic>/gazebo/command/motor_speed</commandSubTopic>
      <motorNumber>2</motorNumber>
      <rotorDragCoefficient>0.000175</rotorDragCoefficient>
      <rollingMomentCoefficient>1e-06</rollingMomentCoefficient>
      <motorSpeedPubTopic>/motor_speed/2</motorSpeedPubTopic>
      <rotorVelocitySlowdownSim>10</rotorVelocitySlowdownSim>
    </plugin>
    <plugin name='back_right_motor_model' filename='libgazebo_motor_model.so'>
      <robotNamespace/>
      <jointName>propeller_3</jointName>
      <linkName>propeller_3_link</linkName>
      <turningDirection>cw</turningDirection>
      <timeConstantUp>0.0125</timeConstantUp>
      <timeConstantDown>0.025</timeConstantDown>
      <maxRotVelocity>1100</maxRotVelocity>
      <motorConstant>5.84e-06</motorConstant>
      <momentConstant>0.06</momentConstant>
      <commandSubTopic>/gazebo/command/motor_speed</commandSubTopic>
      <motorNumber>3</motorNumber>
      <rotorDragCoefficient>0.000175</rotorDragCoefficient>
      <rollingMomentCoefficient>1e-06</rollingMomentCoefficient>
      <motorSpeedPubTopic>/motor_speed/3</motorSpeedPubTopic>
      <rotorVelocitySlowdownSim>10</rotorVelocitySlowdownSim>
    </plugin>
    <include>
      <uri>model://gps</uri>
      <pose>0.05 0 0.04 0 0 0</pose>
      <name>gps0</name>
    </include>
    <joint name='gps0_joint' type='fixed'>
      <child>gps0::link</child>
      <parent>base_link</parent>
    </joint>
    <plugin name='groundtruth_plugin' filename='libgazebo_groundtruth_plugin.so'>
      <robotNamespace/>
    </plugin>
    <plugin name='magnetometer_plugin' filename='libgazebo_magnetometer_plugin.so'>
      <robotNamespace/>
      <pubRate>100</pubRate>
      <noiseDensity>0.0004</noiseDensity>
      <randomWalk>6.4e-06</randomWalk>
      <biasCorrelationTime>600</biasCorrelationTime>
      <magTopic>/mag</magTopic>
    </plugin>
      <plugin name='barometer_plugin' filename='libgazebo_barometer_plugin.so'>
      <robotNamespace/>
      <pubRate>50</pubRate>
      <baroTopic>/baro</baroTopic>
    </plugin>
    <plugin name='mavlink_interface' filename='libgazebo_mavlink_interface.so'>
      <robotNamespace/>
      <imuSubTopic>/imu</imuSubTopic>
      <magSubTopic>/mag</magSubTopic>
      <baroSubTopic>/baro</baroSubTopic>
      <mavlink_addr>INADDR_ANY</mavlink_addr>
      <mavlink_tcp_port>4560</mavlink_tcp_port>
      <mavlink_udp_port>14560</mavlink_udp_port>
      <serialEnabled>0</serialEnabled>
      <serialDevice>/dev/ttyACM0</serialDevice>
      <baudRate>921600</baudRate>
      <qgc_addr>INADDR_ANY</qgc_addr>
      <qgc_udp_port>14550</qgc_udp_port>
      <sdk_addr>INADDR_ANY</sdk_addr>
      <sdk_udp_port>14540</sdk_udp_port>
      <hil_mode>0</hil_mode>
      <hil_state_level>0</hil_state_level>
      <send_vision_estimation>0</send_vision_estimation>
      <send_odometry>1</send_odometry>
      <enable_lockstep>1</enable_lockstep>
      <use_tcp>1</use_tcp>
      <motorSpeedCommandPubTopic>/gazebo/command/motor_speed</motorSpeedCommandPubTopic>
      <control_channels>
        <channel name='rotor1'>
          <input_index>0</input_index>
          <input_offset>0</input_offset>
          <input_scaling>1000</input_scaling>
          <zero_position_disarmed>0</zero_position_disarmed>
          <zero_position_armed>100</zero_position_armed>
          <joint_control_type>velocity</joint_control_type>
        </channel>
          <channel name='rotor2'>
          <input_index>1</input_index>
          <input_offset>0</input_offset>
          <input_scaling>1000</input_scaling>
          <zero_position_disarmed>0</zero_position_disarmed>
          <zero_position_armed>100</zero_position_armed>
          <joint_control_type>velocity</joint_control_type>
        </channel>
        <channel name='rotor3'>
          <input_index>2</input_index>
          <input_offset>0</input_offset>
          <input_scaling>1000</input_scaling>
          <zero_position_disarmed>0</zero_position_disarmed>
          <zero_position_armed>100</zero_position_armed>
          <joint_control_type>velocity</joint_control_type>
        </channel>
        <channel name='rotor4'>
          <input_index>3</input_index>
          <input_offset>0</input_offset>
          <input_scaling>1000</input_scaling>
          <zero_position_disarmed>0</zero_position_disarmed>
          <zero_position_armed>100</zero_position_armed>
          <joint_control_type>velocity</joint_control_type>
        </channel>
          <channel name='rotor5'>
          <input_index>4</input_index>
          <input_offset>1</input_offset>
          <input_scaling>324.6</input_scaling>
          <zero_position_disarmed>0</zero_position_disarmed>
          <zero_position_armed>0</zero_position_armed>
          <joint_control_type>velocity</joint_control_type>
          <joint_control_pid>
            <p>0.1</p>
            <i>0</i>
            <d>0</d>
            <iMax>0.0</iMax>
            <iMin>0.0</iMin>
            <cmdMax>2</cmdMax>
            <cmdMin>-2</cmdMin>
          </joint_control_pid>
          <joint_name>zephyr_delta_wing::propeller_joint</joint_name>
          </channel>
        <channel name='rotor6'>
          <input_index>5</input_index>
          <input_offset>0</input_offset>
          <input_scaling>0.524</input_scaling>
          <zero_position_disarmed>0</zero_position_disarmed>
          <zero_position_armed>0</zero_position_armed>
          <joint_control_type>position</joint_control_type>
          <joint_name>zephyr_delta_wing::flap_left_joint</joint_name>
          <joint_control_pid>
            <p>10.0</p>
            <i>0</i>
            <d>0</d>
            <iMax>0</iMax>
            <iMin>0</iMin>
            <cmdMax>20</cmdMax>
            <cmdMin>-20</cmdMin>
          </joint_control_pid>
        </channel>
        <channel name='rotor7'>
          <input_index>6</input_index>
          <input_offset>0</input_offset>
          <input_scaling>0.524</input_scaling>
          <zero_position_disarmed>0</zero_position_disarmed>
          <zero_position_armed>0</zero_position_armed>
          <joint_control_type>position</joint_control_type>
          <joint_name>zephyr_delta_wing::flap_right_joint</joint_name>
          <joint_control_pid>
            <p>10.0</p>
            <i>0</i>
            <d>0</d>
            <iMax>0</iMax>
            <iMin>0</iMin>
            <cmdMax>20</cmdMax>
            <cmdMin>-20</cmdMin>
          </joint_control_pid>
        </channel>
        <channel name='rotor8'>
          <input_index>7</input_index>
          <input_offset>0</input_offset>
          <input_scaling>0.524</input_scaling>
          <zero_position_disarmed>0</zero_position_disarmed>
          <zero_position_armed>0</zero_position_armed>
          <joint_control_type>position</joint_control_type>
        </channel>
      </control_channels>
    </plugin>
    <static>0</static>
    <plugin name='rotors_gazebo_imu_plugin' filename='libgazebo_imu_plugin.so'>
      <robotNamespace/>
      <linkName>/imu_link</linkName>
      <imuTopic>/imu</imuTopic>
      <gyroscopeNoiseDensity>0.00018665</gyroscopeNoiseDensity>
      <gyroscopeRandomWalk>3.8785e-05</gyroscopeRandomWalk>
      <gyroscopeBiasCorrelationTime>1000.0</gyroscopeBiasCorrelationTime>
      <gyroscopeTurnOnBiasSigma>0.0087</gyroscopeTurnOnBiasSigma>
      <accelerometerNoiseDensity>0.00186</accelerometerNoiseDensity>
      <accelerometerRandomWalk>0.006</accelerometerRandomWalk>
      <accelerometerBiasCorrelationTime>300.0</accelerometerBiasCorrelationTime>
      <accelerometerTurnOnBiasSigma>0.196</accelerometerTurnOnBiasSigma>
    </plugin>



        <!-- For Stereo Camera Payload -->
    <include>
      <uri>model://D435i</uri>
      <pose relative_to='depth_camera_joint'>0 0 0 0 0 0</pose>
    </include>
    <joint name="depth_camera_joint" type="fixed">
      <pose relative_to='camera_link'>0 0 0 0 0 1.5708</pose>
      <child>D435i::camera_link</child>
      <parent>base_link</parent>
    </joint> 

          <!-- For IMU-->
    <include>
      <uri>model://imu_gazebo</uri>
      <pose>0 0 -0.05 0 0 0</pose>
    </include>
    <joint name="imu_gazebo_joint" type="fixed">
      <child>imu_gazebo::link</child>
      <parent>base_link</parent>
      <axis>
        <xyz>0 0 1</xyz>
        <limit>
          <upper>0</upper>
          <lower>0</lower>
        </limit>
      </axis>
    </joint>
    
  </model>
</sdf>
<!-- vim: set noet fenc=utf-8 ff=unix sts=0 sw=4 ts=4 : -->
