<?xml version="1.0" encoding="utf-8"?>
<!-- This URDF was automatically created by SolidWorks to URDF Exporter! Originally created by Stephen Brawner (brawner@gmail.com) 
     Commit Version: 1.6.0-4-g7f85cfe  Build Version: 1.6.7995.38578
     For more information, please see http://wiki.ros.org/sw_urdf_exporter -->
<robot
  name="uav">
  <link
    name="base_link">
    <inertial>
      <origin
        xyz="-0.0225178215569021 -6.57896227218568E-06 0.0139624643866879"
        rpy="0 0 0" />
      <mass
        value="0.726623151388469" />
      <inertia
        ixx="0.00127644805029181"
        ixy="3.54202350999824E-08"
        ixz="-7.517755485557E-08"
        iyy="0.00189227634416466"
        iyz="-5.82362066379798E-08"
        izz="0.00309210466393083" />
    </inertial>
    <visual>
      <origin
        xyz="0 0 0"
        rpy="0 0 0" />
      <geometry>
        <mesh
          filename="package://uav/meshes/base_link.STL" />
      </geometry>
      <material
        name="">
        <color
          rgba="1 1 1 1" />
      </material>
    </visual>
    <collision>
      <origin
        xyz="0 0 0"
        rpy="0 0 0" />
      <geometry>
        <mesh
          filename="package://uav/meshes/base_link.STL" />
      </geometry>
    </collision>
  </link>
  <link
    name="propeller_1_link">
    <inertial>
      <origin
        xyz="-2.1074E-09 -1.8149E-09 0.0034909"
        rpy="0 0 0" />
      <mass
        value="0.0012983" />
      <inertia
        ixx="5.4247E-07"
        ixy="-3.2114E-14"
        ixz="8.3771E-14"
        iyy="5.4246E-07"
        iyz="5.8084E-15"
        izz="1.0787E-06" />
    </inertial>
    <visual>
      <origin
        xyz="0 0 0"
        rpy="0 0 0" />
      <geometry>
        <mesh
          filename="package://uav/meshes/propeller_1_link.STL" />
      </geometry>
      <material
        name="">
        <color
          rgba="0.79216 0.81961 0.93333 1" />
      </material>
    </visual>
    <collision>
      <origin
        xyz="0 0 0"
        rpy="0 0 0" />
      <geometry>
        <mesh
          filename="package://uav/meshes/propeller_1_link.STL" />
      </geometry>
    </collision>
  </link>
  <joint
    name="propeller_1"
    type="continuous">
    <origin
      xyz="0.081317 0.081317 -0.0264"
      rpy="0 0 0" />
    <parent
      link="base_link" />
    <child
      link="propeller_1_link" />
    <axis
      xyz="0 0 -1" />
  </joint>
  <link
    name="propeller_2_link">
    <inertial>
      <origin
        xyz="-1.0971E-09 -7.3704E-10 0.0034909"
        rpy="0 0 0" />
      <mass
        value="0.0012983" />
      <inertia
        ixx="5.4247E-07"
        ixy="-1.5213E-13"
        ixz="6.0754E-14"
        iyy="5.4246E-07"
        iyz="2.55E-14"
        izz="1.0787E-06" />
    </inertial>
    <visual>
      <origin
        xyz="0 0 0"
        rpy="0 0 0" />
      <geometry>
        <mesh
          filename="package://uav/meshes/propeller_2_link.STL" />
      </geometry>
      <material
        name="">
        <color
          rgba="0.79216 0.81961 0.93333 1" />
      </material>
    </visual>
    <collision>
      <origin
        xyz="0 0 0"
        rpy="0 0 0" />
      <geometry>
        <mesh
          filename="package://uav/meshes/propeller_2_link.STL" />
      </geometry>
    </collision>
  </link>
  <joint
    name="propeller_2"
    type="continuous">
    <origin
      xyz="0.081317 -0.081317 -0.0264"
      rpy="0 0 0" />
    <parent
      link="base_link" />
    <child
      link="propeller_2_link" />
    <axis
      xyz="0 0 -1" />
  </joint>
  <link
    name="propeller_3_link">
    <inertial>
      <origin
        xyz="1.367E-10 -6.9573E-10 0.0034909"
        rpy="0 0 0" />
      <mass
        value="0.0012983" />
      <inertia
        ixx="5.4246E-07"
        ixy="1.5689E-13"
        ixz="4.6336E-14"
        iyy="5.4246E-07"
        iyz="-1.3257E-14"
        izz="1.0787E-06" />
    </inertial>
    <visual>
      <origin
        xyz="0 0 0"
        rpy="0 0 0" />
      <geometry>
        <mesh
          filename="package://uav/meshes/propeller_3_link.STL" />
      </geometry>
      <material
        name="">
        <color
          rgba="0.79216 0.81961 0.93333 1" />
      </material>
    </visual>
    <collision>
      <origin
        xyz="0 0 0"
        rpy="0 0 0" />
      <geometry>
        <mesh
          filename="package://uav/meshes/propeller_3_link.STL" />
      </geometry>
    </collision>
  </link>
  <joint
    name="propeller_3"
    type="continuous">
    <origin
      xyz="-0.081317 -0.081317 -0.0264"
      rpy="0 0 0" />
    <parent
      link="base_link" />
    <child
      link="propeller_3_link" />
    <axis
      xyz="0 0 -1" />
  </joint>
  <link
    name="propeller_4_link">
    <inertial>
      <origin
        xyz="1.93495963696222E-09 -2.09565381714683E-09 0.00349092030652917"
        rpy="0 0 0" />
      <mass
        value="0.00129830968932795" />
      <inertia
        ixx="5.42464801225506E-07"
        ixy="5.45914233770257E-16"
        ixz="-6.31179173579807E-16"
        iyy="5.42464983352553E-07"
        iyz="8.0384792707402E-14"
        izz="1.0786772367004E-06" />
    </inertial>
    <visual>
      <origin
        xyz="0 0 0"
        rpy="0 0 0" />
      <geometry>
        <mesh
          filename="package://uav/meshes/propeller_4_link.STL" />
      </geometry>
      <material
        name="">
        <color
          rgba="0.792156862745098 0.819607843137255 0.933333333333333 1" />
      </material>
    </visual>
    <collision>
      <origin
        xyz="0 0 0"
        rpy="0 0 0" />
      <geometry>
        <mesh
          filename="package://uav/meshes/propeller_4_link.STL" />
      </geometry>
    </collision>
  </link>
  <joint
    name="propeller_4"
    type="continuous">
    <origin
      xyz="-0.081317 0.081317 -0.0264"
      rpy="0 0 0" />
    <parent
      link="base_link" />
    <child
      link="propeller_4_link" />
    <axis
      xyz="0 0 -1" />
  </joint>
  <link
    name="lidar_link">
    <inertial>
      <origin
        xyz="-0.000225895985044744 -2.48539042069229E-07 -0.0356306802252529"
        rpy="0 0 0" />
      <mass
        value="0.126556231362929" />
      <inertia
        ixx="3.65033273726769E-05"
        ixy="-9.06996386175696E-11"
        ixz="3.04767232794276E-07"
        iyy="3.97162828413759E-05"
        iyz="1.45228125953335E-10"
        izz="5.81891052137894E-05" />
    </inertial>
    <visual>
      <origin
        xyz="0 0 0"
        rpy="0 0 0" />
      <geometry>
        <mesh
          filename="package://uav/meshes/lidar_link.STL" />
      </geometry>
      <material
        name="">
        <color
          rgba="0.792156862745098 0.819607843137255 0.933333333333333 1" />
      </material>
    </visual>
    <collision>
      <origin
        xyz="0 0 0"
        rpy="0 0 0" />
      <geometry>
        <mesh
          filename="package://uav/meshes/lidar_link.STL" />
      </geometry>
    </collision>
  </link>
  <joint
    name="lidar"
    type="fixed">
    <origin
      xyz="0.080904 0 0.074681"
      rpy="0 0.2618 0" />
    <parent
      link="base_link" />
    <child
      link="lidar_link" />
    <axis
      xyz="0 0 0" />
  </joint>
  <link
    name="camera_link">
    <inertial>
      <origin
        xyz="0.000136232063015659 -0.0017048035419846 -0.011444044647428"
        rpy="0 0 0" />
      <mass
        value="0.107909832749777" />
      <inertia
        ixx="7.02561489057724E-05"
        ixy="2.88922877896695E-10"
        ixz="-4.93709713285397E-08"
        iyy="7.70986396723321E-06"
        iyz="-1.79670593839534E-08"
        izz="7.125435257498E-05" />
    </inertial>
    <visual>
      <origin
        xyz="0 0 0"
        rpy="0 0 0" />
      <geometry>
        <mesh
          filename="package://uav/meshes/camera_link.STL" />
      </geometry>
      <material
        name="">
        <color
          rgba="0.866666666666667 0.909803921568627 1 1" />
      </material>
    </visual>
    <collision>
      <origin
        xyz="0 0 0"
        rpy="0 0 0" />
      <geometry>
        <mesh
          filename="package://uav/meshes/camera_link.STL" />
      </geometry>
    </collision>
  </link>
  <joint
    name="camera"
    type="fixed">
    <origin
      xyz="0.15532 0.0017162 -0.0013741"
      rpy="0 1.5708 0" />
    <parent
      link="base_link" />
    <child
      link="camera_link" />
    <axis
      xyz="0 0 0" />
  </joint>
</robot>